Workbook

Sheet 🎯 CONTROL CENTER
A1: 🚀 WORKLOAD CALCULATOR
A2: Sistem Perhitungan Beban Kerja Terintegrasi untuk PPIC & Marketing | Galangan Kapal
A4: 📍 NAVIGATION PANEL | F4: 📊 STATUS REAL-TIME
A5: No | B5: Sheet | C5: Fungsi | D5: Waktu | F5: Nama Kapal: | G5: ='📝 INPUT DATA'!C6
A6: 1 | B6: 📝 INPUT DATA | C6: Input dimensi kapal | D6: 5 menit | F6: Jenis Kapal: | G6: ='📝 INPUT DATA'!C7
A7: 2 | B7: ⚡ QUICK QUOTE | C7: Estimasi cepat ±20% | D7: Otomatis | F7: Dimensi: | G7: =CONCATENATE('📝 INPUT DATA'!C8," × ",'📝 INPUT DATA'!C9," × ",'📝 INPUT DATA'!C10," m")
A8: 3 | B8: 🎨 DETAIL B&P | C8: Detail Blasting & Painting | D8: 15 menit | F8: Total Luasan B&P: | G8: ='⚡ QUICK QUOTE'!D17 | H8: m²
A9: 4 | B9: 🔧 DETAIL PIPING | C9: Detail pekerjaan pipa | D9: 10 menit | F9: Total Man-Hour: | G9: ='⚡ QUICK QUOTE'!D18 | H9: MH
A10: 5 | B10: ⚙️ DETAIL REPLATING | C10: Detail replating material | D10: 10 menit | F10: Estimasi Harga: | G10: ='⚡ QUICK QUOTE'!F34 | H10: Rp
A11: 6 | B11: 💲 MASTER HARGA | C11: Database harga satuan | D11: Update berkala | F11: Status: | G11: READY | H11: ✅
A12: 7 | B12: 📄 QUOTATION | C12: Generate penawaran | D12: Otomatis
A13: 8 | B13: 📊 ANALYTICS | C13: Analisis & laporan | D13: Otomatis
A14: 9 | B14: 📖 METODOLOGI | C14: Basis rumus & referensi | D14: Referensi
A15: ⚡ QUICK ACTIONS
B16: 🆕 New Project | C16: Mulai proyek baru - Reset semua data
B17: 📋 Copy to MKT-FM-002 | C17: Salin ke template penawaran resmi
B18: 📊 Generate Report | C18: Buat laporan lengkap PDF
B19: 💾 Save Version | C19: Simpan versi dengan timestamp
A21: 💡 TIPS PENGGUNAAN
B22: • Untuk PENAWARAN CEPAT: Cukup isi sheet '📝 INPUT DATA' → lihat '⚡ QUICK QUOTE' (akurasi ±20-30%)
B23: • Untuk AKURASI: Baca '📖 METODOLOGI' untuk basis rumus → akurasi hasil ±5-10% bila input survey lengkap
B24: • Semua formula sudah terhubung otomatis - JANGAN mengubah cell hijau
B25: • Selalu verifikasi hasil dengan validation check di sheet '🔬 SIMPSON' (Row 44-51)
B26: • Backup file sebelum mengubah Master Parameter

Sheet 📝 INPUT DATA
A1: 📝 INPUT DATA KAPAL
A2: ⚠️ ISI SEMUA KOLOM KUNING - Data akan otomatis perhitung di semua sheet
A4: A. DATA KAPAL UTAMA | G4: 📊 VESSEL FACTOR LOOKUP TABLE
A5: No | B5: Parameter | C5: Nilai | D5: Satuan | E5: Keterangan | G5: Faktor koreksi untuk perhitungan WSA berdasarkan jenis kapal
A6: 1 | B6: Nama Kapal | C6: TB. TRUST 17 | D6: - | E6: Nama kapal customer
A7: 2 | B7: Jenis Kapal | C7: Tugboat | D7: - | E7: Pilih dari dropdown
A8: 3 | B8: Panjang (L) | C8: 28 | D8: m | E8: Panjang keseluruhan atau LWL
A9: 4 | B9: Lebar (B) | C9: 8.5 | D9: m | E9: Lebar terlebar
A10: 5 | B10: Depth (D) | C10: 4 | D10: m | E10: Tinggi kapal dari baseline ke main deck
A11: 6 | B11: Sarat (T) | C11: =IFERROR(ROUND(C10*VLOOKUP(C7,'🔧 VESSEL FACTORS'!$A$5:$H$13,7,FALSE),2),"") | D11: m | E11: AUTO: Depth × Faktor Draft (T/D) dari VESSEL FACTORS
A12: 7 | B12: Freeboard | C12: =IFERROR(ROUND(C10-C11,2),"") | D12: m | E12: AUTO: Depth - Sarat
A13: 8 | B13: Kondisi Kapal | C13: Sedang | D13: - | E13: Estimasi kondisi kapal
A17: B. KOEFISIEN OTOMATIS (Berdasarkan Jenis Kapal)
A18: No | B18: Parameter | C18: Nilai | D18: Satuan | E18: Keterangan
A19: 1 | B19: Block Coefficient (Cb) | C19: =IFERROR(VLOOKUP(C7,'🔧 VESSEL FACTORS'!$A$5:$H$13,2,FALSE),"") | D19: - | E19: Block Coefficient dari jenis kapal
A20: 2 | B20: Faktor Appendage | C20: =IFERROR(VLOOKUP(C7,'🔧 VESSEL FACTORS'!$A$5:$H$13,3,FALSE),"") | D20: - | E20: Koreksi appendage (skeg/rudder/bilge keel)
A21: 3 | B21: Faktor Topside | C21: =IFERROR(VLOOKUP(C7,'🔧 VESSEL FACTORS'!$A$5:$H$13,4,FALSE),"") | D21: x | E21: Faktor luas topside
A22: 4 | B22: Faktor Bulwark | C22: =IFERROR(VLOOKUP(C7,'🔧 VESSEL FACTORS'!$A$5:$H$13,5,FALSE),"") | D22: x | E22: Faktor luas bulwark
A23: 5 | B23: Faktor Haluan | C23: =IFERROR(VLOOKUP(C7,'🔧 VESSEL FACTORS'!$A$5:$H$13,6,FALSE),"") | D23: x | E23: Faktor luas haluan
A24: 6 | B24: Faktor Kondisi | C24: =IFERROR(VLOOKUP(C13,'🔧 VESSEL FACTORS'!$I$3:$J$6,2,FALSE),"") | D24: x | E24: Multiplier man-hour
A27: C. PERHITUNGAN DASAR (Otomatis) — Rumus Taylor + Faktor Appendage
A28: No | B28: Parameter | C28: Rumus | D28: Hasil | E28: Satuan
A29: 1 | B29: Girth (Keliling) | C29: B + 2×T | D29: =IFERROR(C9+(2*C11),"") | E29: m
A30: 2 | B30: WSA (Wet Surface Area) | C30: Taylor: [3.223·√(V·L)+0.46·L·B] × F_App | D30: =IFERROR((3.223*SQRT((C8*C9*C11*C19)*C8)+0.46*C8*C9)*C20,"") | E30: m²
A31: 3 | B31: Total Luasan B&P (est) | C31: WSA_uw + L·F·F_ts + L·B + B·F + B·F·F_hal/2 + L·1·4 (bulwark) | D31: =IFERROR(D30 + C8*C12*C21 + C8*C9 + C9*C12 + (C9*C12/2)*C23 + C8*1.0*4, "") | E31: m²
A32: 4 | B32: Man-Hour B&P (est) | C32: Luasan × 0.15 MH/m² × Faktor_Kondisi | D32: =IFERROR(D31*0.15*C24,"") | E32: MH
A33: 5 | B33: Man-Day B&P | C33: MH / 8 | D33: =IFERROR(D32/8,"") | E33: MD

Sheet 📖 METODOLOGI
A1: 📖 METODOLOGI & BASIS PERHITUNGAN
A2: Dokumen teknis penjelasan rumus, asumsi, dan referensi yang dipakai di seluruh kalkulator. WAJIB dibaca sebelum menggunakan hasil untuk quotation.
A4: 1. GEOMETRI KAPAL — Hydrostatics
A5: Parameter | B5: Simbol | C5: Rumus | D5: Satuan | E5: Basis / Referensi | F5: Catatan
A6: Sarat desain | B6: T | C6: T = Depth × Faktor_Draft(jenis kapal) | D6: m | E6: Tabel VESSEL FACTORS kol G (rasio T/D empiris per jenis) | F6: Tidak tetap; turunkan dari draft mark aktual bila ada
A7: Freeboard | B7: f | C7: f = D − T | D7: m | E7: IMO Load Line Convention (ILLC 1966) | F7: Digunakan untuk tinggi topside/transom
A8: Block Coefficient | B8: Cb | C8: Cb = ∇ / (L·B·T) | D8: - | E8: Lookup per jenis (Barrass & Derrett, Ship Stability, 2006) | F8: Cb tipikal: Tug 0.55; Cargo 0.65; Tanker 0.78; Barge 0.90
A9: Girth midship | B9: G | C9: G = B + 2T | D9: m | E9: Approx. keliling penampang lambung midship | F9: Input sederhana untuk estimasi WSA
A10: WSA Underwater | B10: S | C10: S = [3.223·√(∇·L) + 0.46·L·B] × F_Appendage | D10: m² | E10: Formula Taylor (1893) × faktor appendage | F10: Dikalibrasi vs data aktual TB. UVM 88: Taylor 351 × 1.10 = 386 m² vs actual 388 m² (Δ 0.5%)
A11: Volume (Simpson) | B11: ∇ | C11: ∇ = (h/3)·Σ(A(x)·SM) | D11: m³ | E11: Simpson's 1/3 rule, 11 stasiun (10 interval genap) | F11: SM = 1,4,2,4,2,4,2,4,2,4,1 ; h = L/10
A12: Displacement | B12: Δ | C12: Δ = ∇ × 1.025 | D12: ton | E12: Densitas air laut ρ = 1.025 t/m³ (IMO) | F12: Gunakan ρ = 1.000 untuk air tawar
A14: 2. SHAPE GENERATOR — Fungsi f(x/L)
A15: Zona | B15: Rentang x/L | C15: f(x/L) | D15: Keterangan
A16: Stern ke Midship | B16: 0 ≤ x/L ≤ 0.2 | C16: f = F_stern + (F_mid − F_stern)·(x/L)/0.2 | D16: Interpolasi linear stern → midship
A17: Midship | B17: 0.2 ≤ x/L ≤ 0.8 | C17: f = F_midship | D17: Bagian paralel (body amidships)
A18: Midship ke Bow | B18: 0.8 ≤ x/L ≤ 1.0 | C18: f = F_mid − (F_mid − F_bow)·(x/L − 0.8)/0.2 | D18: Interpolasi linear midship → bow
A19: F_bow, F_stern, F_midship diambil otomatis dari tabel Type System (sheet 🔬 SIMPSON) berdasarkan Jenis Kapal. Perubahan jenis → shape function berubah otomatis.
A22: 3. LUASAN BLASTING & PAINTING
A23: Komponen | B23: Rumus | C23: Basis
A24: Lambung Bawah (underwater) | B24: Taylor × F_Appendage (atau Simpson × F_App) | C24: Integrasi numerik; akurasi 90-95%
A25: Skeg (Tugboat only) | B25: 0.15·L × 0.8·T × 4 | C25: Auto untuk Tugboat; untuk jenis lain = 0
A26: Topside Lambung | B26: L × Freeboard × 2 sisi | C26: Input dari INPUT DATA (dinamis)
A27: Transom | B27: B × Freeboard × 1 | C27: Full belakang
A28: Haluan (trapesium) | B28: (B + B·F_haluan)/2 × Freeboard × 0.5 | C28: F_haluan dari tabel VESSEL FACTORS
A29: Bulwark | B29: L × 1.0m × 2 sisi × 2 face (inner+outer) | C29: Asumsi tinggi bulwark 1.0 m (sesuaikan bila perlu)
A30: Main Deck | B30: L × B | C30: Plan view area
A31: Internal Deck | B31: 0.4L × 0.6B (default) | C31: Estimasi cargo hold/ER; override bila tersedia as-built
A32: Superstructure (W/H, Bridge, Lain) | B32: 2·(P+L)·H + P·L (5 sisi) | C32: Input dimensi P,L,H dari survey
A33: Tangki Internal | B33: 2·(P·L + P·H + L·H) × (tiap tangki) | C33: 6 sisi internal dari bulkhead; input dimensi survey
A35: 4. PRODUKTIVITAS & MAN-HOUR
A36: Pekerjaan | B36: Rate | C36: Satuan | D36: Basis
A37: Blasting + Painting (SA 2.0, 2-coat) | B37: 0.15 | C37: MH/m² | D37: Standar industri galangan Asia Tenggara (reviu SNI & OCIMF)
A38: Piping 1/2" (15mm) — joint | B38: 0.50 | C38: MH/joint | D38: Standar TCAEMM / ABS Productivity Standards
A39: Piping 2" (50mm) — joint | B39: 1.20 | C39: MH/joint | D39: TCAEMM
A40: Piping 6" (150mm) — joint | B40: 3.50 | C40: MH/joint | D40: TCAEMM
A41: Piping 12" (300mm) — joint | B41: 8.00 | C41: MH/joint | D41: TCAEMM
A42: Replating baja | B42: 40 | C42: kg/MH | D42: Produktivitas fabrikasi+ereksi+welding kapal repair
A43: Faktor Kondisi Baik | B43: 1.00 | C43: × | D43: Kapal terawat, korosi minimal
A44: Faktor Kondisi Sedang | B44: 1.30 | C44: × | D44: Persiapan surface lebih (desilting, sandblast lebih lama)
A45: Faktor Kondisi Buruk | B45: 1.50 | C45: × | D45: Korosi berat
...

Sheet 🔬 SIMPSON 
A1: 🔬 SIMPSON'S RULE - COMPLETE NAVAL ARCHITECTURE SYSTEM
A2: 📚 Shape Generator + Simpson Integration + Validation System + Type Selector
A4: A. TYPE SYSTEM - Selector Jenis Kapal (Auto-Shape) | I4: ⚡ PARAMETER OTOMATIS (dari Input Data)
A5: Jenis Kapal | B5: Cb | C5: Shape Type | D5: Bow Factor | E5: Stern Factor | F5: Midship Factor | G5: Keterangan | I5: Parameter | J5: Nilai | K5: Satuan | L5: Source
A6: Tongkang/Barge | B6: 0.9 | C6: BOXY | D6: 0.5 | E6: 0.5 | F6: 1 | G6: Bentuk kotak, WSA mendekati teoritis | I6: Jenis Kapal | J6: ='📝 INPUT DATA'!C7 | K6: - | L6: Input
A7: LCT/Landing Craft | B7: 0.85 | C7: FLAT | D7: 0.5 | E7: 0.5 | F7: 1 | G7: Flat bottom, parallel sides | I7: Panjang (L) | J7: ='📝 INPUT DATA'!C8 | K7: m | L7: Input
A8: Tugboat | B8: 0.55 | C8: ROUNDED | D8: 0.3 | E8: 0.35 | F8: 0.72 | G8: Fuller stern, rounded bow | I8: Lebar (B) | J8: ='📝 INPUT DATA'!C9 | K8: m | L8: Input
A9: Cargo Ship | B9: 0.65 | C9: STANDARD | D9: 0.45 | E9: 0.5 | F9: 0.85 | G9: Bentuk standar kapal barang | I9: Sarat (T) | J9: ='📝 INPUT DATA'!C11 | K9: m | L9: Input
A10: Tanker | B10: 0.78 | C10: FULL | D10: 0.5 | E10: 0.5 | F10: 0.95 | G10: Bentuk gemuk, WSA besar | I10: Cb (dari Type) | J10: ='📝 INPUT DATA'!C19 | K10: - | L10: Lookup
A11: Passenger Ship | B11: 0.58 | C11: FINE | D11: 0.35 | E11: 0.4 | F11: 0.75 | G11: Banyak superstructure | I11: Shape Type | J11: =IF($J$10>=0.85,"BOXY",IF($J$10>=0.75,"FULL",IF($J$10>=0.62,"STANDARD",IF($J$10>=0.55,"ROUNDED","FINE")))) | K11: - | L11: Lookup
A12: Fishing Vessel | B12: 0.55 | C12: ROUNDED | D12: 0.3 | E12: 0.35 | F12: 0.7 | G12: Bentuk ramping | I12: Bow Factor (calibrated) | J12: =IFERROR(VLOOKUP($J$6,$A$5:$G$13,4,FALSE),0.3) | K12: - | L12: Lookup dari Type System berdasarkan Jenis Kapal
A13: Supply Vessel | B13: 0.65 | C13: STANDARD | D13: 0.45 | E13: 0.5 | F13: 0.85 | G13: Kombinasi cargo dan tug | I13: Stern Factor (calibrated) | J13: =IFERROR(VLOOKUP($J$6,$A$5:$G$13,5,FALSE),0.35) | K13: - | L13: Lookup dari Type System berdasarkan Jenis Kapal
I14: Midship Factor (calibrated) | J14: =IFERROR(VLOOKUP($J$6,$A$5:$G$13,6,FALSE),0.72) | K14: - | L14: Lookup dari Type System berdasarkan Jenis Kapal
A17: B. SHAPE GENERATOR LAYER - Fungsi b(x) = (B/2) × f(x/L) [11 Stasiun Simpson]
A18: 📐 Shape Function: f(x/L) ditentukan otomatis berdasarkan Type System. Bow/Stern meruncing, Midship maksimal.
A19: Station | B19: x/L | C19: Posisi (m) | D19: f(x/L) Shape | E19: b(x) Half-Breadth | F19: A(x) Area Potong | G19: SM Coeff | H19: A×SM | I19: Girth Factor (0.85+0.25·Cb+0.20·f) | J19: Girth(x) | K19: Girth×SM | L19: Keterangan
A20: 0 | B20: 0 | C20: =B20*$J$7 | D20: =$J$13+($J$14-$J$13)*B20/0.2 | E20: =($J$8/2)*D20 | F20: =2*E20*$J$9*(0.5+0.5*D20) | G20: 1 | H20: =F20*G20 | I20: =0.85+0.25*$J$10+0.20*D20 | J20: =I20*($J$8+2*$J$9) | K20: =J20*G20 | L20: AP (Stern)
A21: 1 | B21: 0.1 | C21: =B21*$J$7 | D21: =$J$13+($J$14-$J$13)*B21/0.2 | E21: =($J$8/2)*D21 | F21: =2*E21*$J$9*(0.5+0.5*D21) | G21: 4 | H21: =F21*G21 | I21: =0.85+0.25*$J$10+0.20*D21 | J21: =I21*($J$8+2*$J$9) | K21: =J21*G21 | L21: Station 1
A22: 2 | B22: 0.2 | C22: =B22*$J$7 | D22: =$J$13+($J$14-$J$13)*B22/0.2 | E22: =($J$8/2)*D22 | F22: =2*E22*$J$9*(0.5+0.5*D22) | G22: 2 | H22: =F22*G22 | I22: =0.85+0.25*$J$10+0.20*D22 | J22: =I22*($J$8+2*$J$9) | K22: =J22*G22 | L22: Station 2
A23: 3 | B23: 0.3 | C23: =B23*$J$7 | D23: =$J$14 | E23: =($J$8/2)*D23 | F23: =2*E23*$J$9*(0.5+0.5*D23) | G23: 4 | H23: =F23*G23 | I23: =0.85+0.25*$J$10+0.20*D23 | J23: =I23*($J$8+2*$J$9) | K23: =J23*G23 | L23: Station 3
A24: 4 | B24: 0.4 | C24: =B24*$J$7 | D24: =$J$14 | E24: =($J$8/2)*D24 | F24: =2*E24*$J$9*(0.5+0.5*D24) | G24: 2 | H24: =F24*G24 | I24: =0.85+0.25*$J$10+0.20*D24 | J24: =I24*($J$8+2*$J$9) | K24: =J24*G24 | L24: Station 4
A25: 5 | B25: 0.5 | C25: =B25*$J$7 | D25: =$J$14 | E25: =($J$8/2)*D25 | F25: =2*E25*$J$9*(0.5+0.5*D25) | G25: 4 | H25: =F25*G25 | I25: =0.85+0.25*$J$10+0.20*D25 | J25: =I25*($J$8+2*$J$9) | K25: =J25*G25 | L25: Midship
A26: 6 | B26: 0.6 | C26: =B26*$J$7 | D26: =$J$14 | E26: =($J$8/2)*D26 | F26: =2*E26*$J$9*(0.5+0.5*D26) | G26: 2 | H26: =F26*G26 | I26: =0.85+0.25*$J$10+0.20*D26 | J26: =I26*($J$8+2*$J$9) | K26: =J26*G26 | L26: Station 6
A27: 7 | B27: 0.7 | C27: =B27*$J$7 | D27: =$J$14 | E27: =($J$8/2)*D27 | F27: =2*E27*$J$9*(0.5+0.5*D27) | G27: 4 | H27: =F27*G27 | I27: =0.85+0.25*$J$10+0.20*D27 | J27: =I27*($J$8+2*$J$9) | K27: =J27*G27 | L27: Station 7
A28: 8 | B28: 0.8 | C28: =B28*$J$7 | D28: =$J$14-($J$14-$J$12)*(B28-0.8)/0.2 | E28: =($J$8/2)*D28 | F28: =2*E28*$J$9*(0.5+0.5*D28) | G28: 2 | H28: =F28*G28 | I28: =0.85+0.25*$J$10+0.20*D28 | J28: =I28*($J$8+2*$J$9) | K28: =J28*G28 | L28: Station 8
A29: 9 | B29: 0.9 | C29: =B29*$J$7 | D29: =$J$14-($J$14-$J$12)*(B29-0.8)/0.2 | E29: =($J$8/2)*D29 | F29: =2*E29*$J$9*(0.5+0.5*D29) | G29: 4 | H29: =F29*G29 | I29: =0.85+0.25*$J$10+0.20*D29 | J29: =I29*($J$8+2*$J$9) | K29: =J29*G29 | L29: Station 9
A30: 10 | B30: 1 | C30: =B30*$J$7 | D30: =$J$14-($J$14-$J$12)*(B30-0.8)/0.2 | E30: =($J$8/2)*D30 | F30: =2*E30*$J$9*(0.5+0.5*D30) | G30: 1 | H30: =F30*G30 | I30: =0.85+0.25*$J$10+0.20*D30 | J30: =I30*($J$8+2*$J$9) | K30: =J30*G30 | L30: FP (Bow)
A31: Σ | B31: TOTAL Σ (Simpson Integration) | H31: =SUM(H20:H30) | K31: =SUM(K20:K30)
A34: C. SIMPSON INTEGRATION RESULTS | I34: 📊 PARAMETRIC COMPARISON
A35: Interval (h) | B35: =$J$7/10 | C35: m | D35: L/10 untuk 11 stasiun | I35: Volume Parametrik | K35: =$J$7*$J$8*$J$9*$J$10 | L35: m³ | M35: L×B×T×Cb
A36: 🎯 VOLUME (Simpson) | B36: =(B35/3)*H31 | C36: m³ | D36: V = (h/3) × Σ(A×SM) | I36: Volume Simpson | K36: =B36 | L36: m³ | M36: Dari integrasi
A37: 🎯 DISPLACEMENT | B37: =B36*1.025 | C37: ton | D37: Disp = V × ρ_air | I37: Selisih Absolut | K37: =ABS(K36-K35) | L37: m³ | M37: |Simpson - Param|
A38: 🎯 WSA Underwater | B38: =(B35/3)*K31 | C38: m² | D38: WSA = (h/3) × Σ(Girth×SM) | I38: Error Relatif | K38: =K37/K35 | L38: % | M38: Target < 5%
A39: 🎯 WSA Total (×2.5) | B39: =B38*2.5 | C39: m² | D39: Estimasi total B&P area | I39: Status | K39: =IF(K38<0.05,"✅ VALID","⚠️ CHECK") | L39: - | M39: Auto validation
A42: D. VALIDATION SYSTEM - Engineering Robustness Checks
A43: No | B43: Validation Check | C43: Formula | D43: Result | E43: Threshold | F43: Status | G43: Keterangan
A44: 1 | B44: Simpson vs Parametrik Error | C44: =K38 | D44: < 5% | E44: =IF(C44<0.05,"✅ PASS","❌ FAIL") | F44: Volume harus konsisten
A45: 2 | B45: Cb Range Check | C45: =$J$10 | D45: 0.5 - 0.95 | E45: =IF(AND(C45>=0.5,C45<=0.95),"✅ PASS","❌ FAIL") | F45: Cb harus dalam range valid
A46: 3 | B46: L/B Ratio | C46: =$J$7/$J$8 | D46: 3 - 10 | E46: =IF(AND(C46>=3,C46<=10),"✅ PASS","⚠️ CHECK") | F46: Rasio panjang/lebar
A47: 4 | B47: B/T Ratio | C47: =$J$8/$J$9 | D47: 2 - 5 | E47: =IF(AND(C47>=2,C47<=5),"✅ PASS","⚠️ CHECK") | F47: Rasio lebar/sarat
...

Sheet 🔧 VESSEL FACTORS
A1: 🔧 VESSEL FACTOR LOOKUP TABLE | I1: 📊 KONDISI KAPAL
A2: Faktor koreksi dikalibrasi dari 8 quotation MNB Shipyard 2026 (TB UVM 88, TB ENTEBE, LCT EUNIKE, BG WIRANDI XV, dll) | I2: Kondisi | J2: Faktor MH | K2: Keterangan
I3: Baik | J3: 1 | K3: Kapal terawat, korosi minimal
A4: Jenis Kapal | B4: Cb | C4: Faktor Appendage | D4: Topside | E4: Bulwark | F4: Haluan | G4: Faktor Draft (T/D) | H4: Keterangan | I4: Sedang | J4: 1.3 | K4: Korosi sedang, perlu persiapan lebih
A5: Tongkang/Barge | B5: 0.9 | C5: 0.96 | D5: 6.3 | E5: 2 | F5: 0.5 | G5: 0.55 | H5: Kalibrasi dari OB WIRANDI XV (67m, 1926m²) | I5: Buruk | J5: 1.5 | K5: Korosi berat, banyak kerusakan
A6: Tugboat | B6: 0.55 | C6: 1.12 | D6: 4.2 | E6: 2.2 | F6: 0.6 | G6: 0.75 | H6: Kalibrasi dari TB UVM 88 & TB ENTEBE EMERALD | I6: Sangat Buruk | J6: 2 | K6: Korosi sangat berat, perlu perbaikan ekstensif
A7: Cargo Ship | B7: 0.65 | C7: 1 | D7: 3.5 | E7: 2 | F7: 0.55 | G7: 0.75 | H7: Estimasi; belum divalidasi lapangan
A8: Tanker | B8: 0.78 | C8: 0.98 | D8: 3 | E8: 1.8 | F8: 0.5 | G8: 0.8 | H8: Estimasi; belum divalidasi lapangan
A9: Bulk Carrier | B9: 0.85 | C9: 0.96 | D9: 3 | E9: 1.8 | F9: 0.5 | G9: 0.8 | H9: Mirip tanker
A10: Passenger Ship | B10: 0.58 | C10: 1.08 | D10: 5 | E10: 2.5 | F10: 0.6 | G10: 0.6 | H10: Estimasi superstructure tinggi
A11: Fishing Vessel | B11: 0.55 | C11: 1.12 | D11: 3.8 | E11: 2 | F11: 0.6 | G11: 0.7 | H11: Estimasi mirip tugboat
A12: LCT/Landing Craft | B12: 0.85 | C12: 0.82 | D12: 5 | E12: 2 | F12: 0.5 | G12: 0.6 | H12: Kalibrasi dari LCT EUNIKE (41m, 419m²)
A13: Supply Vessel | B13: 0.65 | C13: 1.05 | D13: 4 | E13: 2 | F13: 0.55 | G13: 0.72 | H13: Estimasi mirip cargo

Sheet ⚡ QUICK QUOTE
A1: ⚡ QUICK QUOTE - PENAWARAN AWAL (±20-30%)
A2: 📋 Estimasi cepat untuk Marketing (±20-30%). Gunakan sheet DETAIL untuk akurasi ±5-10%.
A4: A. RINGKASAN DATA KAPAL
B5: Nama Kapal: | C5: ='📝 INPUT DATA'!C6
B6: Jenis Kapal: | C6: ='📝 INPUT DATA'!C7
B7: Dimensi (L×B×D): | C7: =CONCATENATE('📝 INPUT DATA'!C8," × ",'📝 INPUT DATA'!C9," × ",'📝 INPUT DATA'!C10," m")
B8: Kondisi: | C8: ='📝 INPUT DATA'!C13
B9: Faktor Kondisi: | C9: ='📝 INPUT DATA'!C24
A11: B. PERHITUNGAN OTOMATIS
A12: No | B12: Item | C12: Rumus | D12: Hasil | E12: Satuan | F12: Keterangan
A13: 1 | B13: Faktor WSA (auto) | C13: Berdasarkan jenis kapal | D13: ='📝 INPUT DATA'!C20 | E13: - | F13: Auto dari jenis kapal
A14: 2 | B14: Faktor Kondisi (auto) | C14: Berdasarkan kondisi | D14: ='📝 INPUT DATA'!C24 | E14: x | F14: Multiplier MH
A15: 3 | B15: Girth (B+2T) | C15: B + 2×T | D15: ='📝 INPUT DATA'!D29 | E15: m | F15: Keliling penampang
A16: 4 | B16: WSA (Wet Surface Area) | C16: L × Girth × Faktor | D16: ='📝 INPUT DATA'!D30 | E16: m² | F16: Luas permukaan basah
A17: 5 | B17: Total Luasan B&P (est) | C17: WSA × 2.5 | D17: ='📝 INPUT DATA'!D31 | E17: m² | F17: Estimasi total luasan
A18: 6 | B18: Man-Hour B&P (est) | C18: Luasan × 0.15 × Kondisi | D18: ='📝 INPUT DATA'!D32 | E18: MH | F18: Estimasi man-hour
A19: 7 | B19: Man-Day B&P | C19: MH / 8 | D19: ='📝 INPUT DATA'!D33 | E19: MD | F19: Konversi ke man-day
A22: C. ESTIMASI BIAYA (Marketing View)
A23: No | B23: Item Pekerjaan | C23: Qty | D23: Satuan | E23: Harga Satuan | F23: Total (Rp)
A24: 1 | B24: Blasting & Painting | C24: =D17 | D24: m² | E24: 120000 | F24: =C24*E24
A25: 2 | B25: Piping Works (est) | C25: =D17*0.02 | D25: joint | E25: 650000 | F25: =C25*E25
A26: 3 | B26: Tank Cleaning (est) | C26: =IFERROR('📝 INPUT DATA'!C8*'📝 INPUT DATA'!C9*'📝 INPUT DATA'!C11*'📝 INPUT DATA'!C19*0.1,0) | D26: m³ | E26: 200000 | F26: =C26*E26
A27: 4 | B27: Replating (est) | C27: =IFERROR('🔬 SIMPSON '!I78*1000*MAX(('📝 INPUT DATA'!C24-1)*0.05,0.02),0) | D27: kg | E27: 32000 | F27: =C27*E27
A28: 5 | B28: Man-Hour Cost | C28: =D18 | D28: MH | E28: 50000 | F28: =C28*E28
B30: SUBTOTAL BIAYA PRODUKSI | F30: =SUM(F24:F28)
B31: Overhead (15%) | F31: =F30*0.15
B32: Margin (25%) | F32: =F30*0.25
A34: 🎯 HARGA PENAWARAN AWAL | F34: =F30+F31+F32

Sheet 🎨 DETAIL B&P
A1: 🎨 CALCULATOR DETAIL - BLASTING & PAINTING (Penawaran Akhir)
A2: 📋 Untuk PPIC: Input data detail dari survey. Hasil otomatis terhitung dengan akurasi ±5-10%.
A4: A. DATA KAPAL (Dari Input Data) | E4: ⚡ FAKTOR OTOMATIS | H4: 📊 FAKTOR JENIS KAPAL
A5: Jenis Kapal: | B5: ='📝 INPUT DATA'!C7 | E5: Panjang (L): | F5: ='📝 INPUT DATA'!C8 | G5: m | H5: Jenis Kapal: | I5: ='📝 INPUT DATA'!C7
A6: Kondisi: | B6: ='📝 INPUT DATA'!C13 | E6: Lebar (B): | F6: ='📝 INPUT DATA'!C9 | G6: m | H6: Faktor WSA: | I6: ='📝 INPUT DATA'!C20
A7: Faktor WSA: | B7: ='📝 INPUT DATA'!C20 | E7: Sarat (T): | F7: ='📝 INPUT DATA'!C11 | G7: m | H7: Faktor Topside: | I7: ='📝 INPUT DATA'!C21
A8: Faktor Kondisi: | B8: ='📝 INPUT DATA'!C24 | E8: Cb: | F8: ='📝 INPUT DATA'!C19 | G8: - | H8: Faktor Bulwark: | I8: ='📝 INPUT DATA'!C22
G10: 🔬 SIMPSON GENIUS INTEGRATION
A11: B. PERHITUNGAN LUASAN DETAIL (Isi kolom KUNING)
A12: No | B12: Komponen Area | C12: Var 1 | D12: Var 2 | E12: Var 3 | F12: V1 (m) | G12: V2 (m) | H12: V3/Fak | I12: Rumus | J12: Hasil (m²)
B13: 1. UNDERWATER (Bottom-WL)
A14: 1.1 | B14: Lambung Bawah (Underwater) | C14: 🔬 SIMPSON | D14: AUTO | E14: WSA | F14: ='🔬 SIMPSON '!B38 | G14: - | H14: ='📝 INPUT DATA'!C20 | I14: =F14*H14 | J14: 🔬 WSA Simpson × Faktor Appendage (skeg/rudder/bilge)
A15: 1.2 | B15: Underwater Skeg | C15: 🔬 AUTO | D15: Skeg | E15: Calc | F15: =IF(B5="Tugboat",F5*0.15,0) | G15: =IF(B5="Tugboat",F7*0.8,0) | H15: =IF(B5="Tugboat",4,0) | I15: =F15*G15*H15 | J15: 🔬 AUTO: Skeg area = 0.15L × 0.8T × 4 (Tugboat only)
B16: TOTAL UNDERWATER | I16: =SUM(I14:I15)
B17: 2. TOPSIDE (WL-Deck Edge)
A18: 2.1 | B18: Topside (Lambung Atas) | C18: Panjang | D18: Freeboard | E18: F_Topside | F18: ='📝 INPUT DATA'!C8 | G18: ='📝 INPUT DATA'!C12 | H18: ='📝 INPUT DATA'!C21 | I18: =F18*G18*H18 | J18: Topside = L × Freeboard × F_Topside (mencakup sheer/camber)
A19: 2.2 | B19: Transom (Buritan) | C19: Lebar | D19: Tinggi | E19: - | F19: ='📝 INPUT DATA'!C9 | G19: ='📝 INPUT DATA'!C12 | H19: 1 | I19: =F19*G19*H19 | J19: L,T: Tampak Belakang (Rear View)
A20: 2.3 | B20: Haluan (Trapesium) | C20: B_atas + B_bwh | D20: Tinggi | E20: ÷2 | F20: ='📝 INPUT DATA'!C9*(1+'📝 INPUT DATA'!C23) | G20: ='📝 INPUT DATA'!C12 | H20: 0.5 | I20: =F20*G20*H20 | J20: Haluan = (B + B·FHaluan)/2 × Freeboard (trapesium)
B21: TOTAL TOPSIDE | I21: =SUM(I18:I20)
B22: 3. BULWARK (Pagar Kapal)
A23: 3.1 | B23: Bulwark Luar | C23: Panjang | D23: Tinggi | E23: ×2 sisi | F23: ='📝 INPUT DATA'!C8 | G23: 1 | H23: 2 | I23: =F23*G23*H23 | J23: P: HORIZONTAL deck edge, T: deck→cap
A24: 3.2 | B24: Bulwark Dalam | C24: Panjang | D24: Tinggi | E24: ×2 sisi | F24: ='📝 INPUT DATA'!C8 | G24: 1 | H24: 2 | I24: =F24*G24*H24 | J24: Sama dengan bulwark luar
B25: TOTAL BULWARK | I25: =SUM(I23:I24)
B26: 4. DECK (Geladak)
A27: 4.1 | B27: Main Deck (External) | C27: Panjang | D27: Lebar | E27: - | F27: ='📝 INPUT DATA'!C8 | G27: ='📝 INPUT DATA'!C9 | H27: 1 | I27: =F27*G27*H27 | J27: P: HORIZONTAL sepanjang CL, L: melintang (Plan View)
A28: 4.2 | B28: Internal Deck | C28: Panjang | D28: Lebar | E28: - | F28: =0.4*'📝 INPUT DATA'!C8 | G28: =0.6*'📝 INPUT DATA'!C9 | H28: 1 | I28: =F28*G28*H28 | J28: Dimensi internal deck
B29: TOTAL DECK | I29: =SUM(I27:I28)
B30: 5. SUPERSTRUCTURE
A31: 5.1 | B31: Rumah Winch | C31: P | D31: L | E31: H | F31: =0.25*'📝 INPUT DATA'!C8 | G31: =0.3*'📝 INPUT DATA'!C9 | H31: 3 | I31: =2*(F31+G31)*H31+F31*G31 | J31: P,L,H: Dimensi struktur (Side/Front View)
A32: 5.2 | B32: Anjungan/Bridge | C32: P | D32: L | E32: H | F32: =0.35*'📝 INPUT DATA'!C8 | G32: =0.5*'📝 INPUT DATA'!C9 | H32: 4 | I32: =2*(F32+G32)*H32+F32*G32 | J32: P,L,H: Dimensi struktur (Side/Front View)
A33: 5.3 | B33: Struktur Lainnya | C33: P | D33: L | E33: H | F33: 5 | G33: 4 | H33: 3 | I33: =2*(F33+G33)*H33+F33*G33 | J33: P,L,H: Dimensi struktur (Side/Front View)
B34: TOTAL SUPERSTRUCTURE | I34: =SUM(I31:I33)
B35: 6. TANGKI (Internal)
A36: 6.1 | B36: Tangki Ballast | C36: P | D36: L | E36: H | F36: =0.3*'📝 INPUT DATA'!C8 | G36: =0.7*'📝 INPUT DATA'!C9 | H36: ='📝 INPUT DATA'!C11 | I36: =2*(F36*G36+F36*H36+G36*H36) | J36: P,L,H: INTERNAL dari bulkhead (Internal View)
A37: 6.2 | B37: Tangki BBM | C37: P | D37: L | E37: H | F37: =0.15*'📝 INPUT DATA'!C8 | G37: =0.6*'📝 INPUT DATA'!C9 | H37: ='📝 INPUT DATA'!C11*0.8 | I37: =2*(F37*G37+F37*H37+G37*H37) | J37: P,L,H: INTERNAL (Internal View)
A38: 6.3 | B38: Tangki Air Tawar | C38: P | D38: L | E38: H | F38: =0.1*'📝 INPUT DATA'!C8 | G38: =0.4*'📝 INPUT DATA'!C9 | H38: 2 | I38: =2*(F38*G38+F38*H38+G38*H38) | J38: P,L,H: INTERNAL (Internal View)
B39: TOTAL TANGKI | I39: =SUM(I36:I38)
A41: ═══ GRAND TOTAL LUASAN BLASTING & PAINTING ═══ | I41: =I16+I21+I25+I29+I34+I39 | J41: m²
A43: C. ESTIMASI MAN-HOUR B&P
A44: Total Luasan: | B44: =I41 | C44: m²
...

Sheet 🔧 DETAIL PIPING
A1: 🔧 CALCULATOR DETAIL - PIPING (Joint & Man-Hour)
A2: 📋 Input jumlah joint per diameter. MH otomatis terhitung berdasarkan standar TCAEMM.
A4: A. PERHITUNGAN JOINT & MAN-HOUR PIPING
A5: No | B5: Diameter | C5: Jumlah Joint | D5: MH/Joint | E5: MH/Fitting | F5: Total MH Joint | G5: Total MH Fitting | H5: Total MH | I5: Catatan
A6: 1.1 | B6: 1/2" (15mm) | D6: 0.5 | E6: 0.25 | F6: =C6*D6 | G6: =C6*E6 | H6: =F6+G6 | I6: Pipa kecil
A7: 1.2 | B7: 3/4" (20mm) | D7: 0.6 | E7: 0.3 | F7: =C7*D7 | G7: =C7*E7 | H7: =F7+G7 | I7: Pipa kecil
A8: 1.3 | B8: 1" (25mm) | D8: 0.8 | E8: 0.4 | F8: =C8*D8 | G8: =C8*E8 | H8: =F8+G8 | I8: Pipa kecil
A9: 1.4 | B9: 1.5" (40mm) | D9: 1 | E9: 0.5 | F9: =C9*D9 | G9: =C9*E9 | H9: =F9+G9 | I9: Pipa sedang
A10: 1.5 | B10: 2" (50mm) | D10: 1.2 | E10: 0.6 | F10: =C10*D10 | G10: =C10*E10 | H10: =F10+G10 | I10: Pipa sedang
A11: 1.6 | B11: 2.5" (65mm) | D11: 1.5 | E11: 0.75 | F11: =C11*D11 | G11: =C11*E11 | H11: =F11+G11 | I11: Pipa sedang
A12: 1.7 | B12: 3" (80mm) | D12: 1.8 | E12: 0.9 | F12: =C12*D12 | G12: =C12*E12 | H12: =F12+G12 | I12: Pipa sedang
A13: 1.8 | B13: 4" (100mm) | D13: 2.5 | E13: 1.25 | F13: =C13*D13 | G13: =C13*E13 | H13: =F13+G13 | I13: Pipa besar
A14: 1.9 | B14: 5" (125mm) | D14: 3 | E14: 1.5 | F14: =C14*D14 | G14: =C14*E14 | H14: =F14+G14 | I14: Pipa besar
A15: 1.10 | B15: 6" (150mm) | D15: 3.5 | E15: 1.75 | F15: =C15*D15 | G15: =C15*E15 | H15: =F15+G15 | I15: Pipa besar
A16: 1.11 | B16: 8" (200mm) | D16: 5 | E16: 2.5 | F16: =C16*D16 | G16: =C16*E16 | H16: =F16+G16 | I16: Pipa besar
A17: 1.12 | B17: 10" (250mm) | D17: 6.5 | E17: 3.25 | F17: =C17*D17 | G17: =C17*E17 | H17: =F17+G17 | I17: Pipa besar
A18: 1.13 | B18: 12" (300mm) | D18: 8 | E18: 4 | F18: =C18*D18 | G18: =C18*E18 | H18: =F18+G18 | I18: Pipa besar
A19: TOTAL MAN-HOUR PIPING | F19: =SUM(F6:F18) | G19: =SUM(G6:G18) | H19: =SUM(H6:H18) | I19: MH
A21: Konversi ke Man-Day (8 jam): | H21: =H19/8 | I21: MD

Sheet ⚙️ DETAIL REPLATING
A1: ⚙️ REPLATING CALCULATOR
A2: Perhitungan Berat Material Replating Otomatis • Terintegrasi dengan Quotation
I3: 📊 RINGKASAN CEPAT
A4: A. PLATE (Plat Baja) | I4: Total Berat Plate: | J4: =SUM(L8:L18) | K4: kg
A5: Densitas: 7.85 g/cm³ • Loss Factor: <600mm = 1.2, ≥600mm = 1.05 | I5: Total Berat Profile: | J5: =SUM(L22:L41) | K5: kg
I6: GRAND TOTAL: | J6: =J4+J5 | K6: kg
A7: No | B7: Jenis Plate | C7: Kelas | D7: Panjang (m) | E7: Lebar (m) | F7: Tebal (mm) | G7: Qty (sht) | H7: Berat (kg) | I7: Loss Factor | J7: Berat Aktual (kg) | K7: Harga/kg (Rp) | L7: Total Harga (Rp)
A8: 1 | B8: Plate Grade A - 6mm | C8: Non-Klass | D8: 1.5 | E8: 0.8 | F8: 6 | G8: 1 | H8: =D8*E8*F8*7.85 | I8: =IF(E8<0.6,1.2,1.05) | J8: =H8*I8*G8 | K8: 32000 | L8: =J8*K8
A9: 2 | B9: Plate Grade A - 8mm | C9: Non-Klass | D9: 2 | E9: 1.2 | F9: 8 | G9: 1 | H9: =D9*E9*F9*7.85 | I9: =IF(E9<0.6,1.2,1.05) | J9: =H9*I9*G9 | K9: 32000 | L9: =J9*K9
A10: 3 | B10: Plate Grade A - 10mm | C10: Non-Klass | F10: 10 | H10: =D10*E10*F10*7.85 | I10: =IF(E10<0.6,1.2,1.05) | J10: =H10*I10*G10 | K10: 32000 | L10: =J10*K10
A11: 4 | B11: Plate Grade A - 12mm | C11: Non-Klass | F11: 12 | H11: =D11*E11*F11*7.85 | I11: =IF(E11<0.6,1.2,1.05) | J11: =H11*I11*G11 | K11: 32000 | L11: =J11*K11
A12: 5 | B12: Plate Grade A - 14mm | C12: Non-Klass | F12: 14 | H12: =D12*E12*F12*7.85 | I12: =IF(E12<0.6,1.2,1.05) | J12: =H12*I12*G12 | K12: 32000 | L12: =J12*K12
A13: 6 | B13: Plate Grade A - 16mm | C13: Non-Klass | F13: 16 | H13: =D13*E13*F13*7.85 | I13: =IF(E13<0.6,1.2,1.05) | J13: =H13*I13*G13 | K13: 32000 | L13: =J13*K13
A14: 7 | B14: Plate BKI - 8mm | C14: Klass BKI | F14: 8 | H14: =D14*E14*F14*7.85 | I14: =IF(E14<0.6,1.2,1.05) | J14: =H14*I14*G14 | K14: 34000 | L14: =J14*K14
A15: 8 | B15: Plate BKI - 10mm | C15: Klass BKI | F15: 10 | H15: =D15*E15*F15*7.85 | I15: =IF(E15<0.6,1.2,1.05) | J15: =H15*I15*G15 | K15: 34000 | L15: =J15*K15
A16: 9 | B16: Plate BKI - 12mm | C16: Klass BKI | F16: 12 | H16: =D16*E16*F16*7.85 | I16: =IF(E16<0.6,1.2,1.05) | J16: =H16*I16*G16 | K16: 34000 | L16: =J16*K16
A17: 10 | B17: Plate IACS - 8mm | C17: IACS Member | F17: 8 | H17: =D17*E17*F17*7.85 | I17: =IF(E17<0.6,1.2,1.05) | J17: =H17*I17*G17 | K17: 36000 | L17: =J17*K17
A18: 11 | B18: Plate IACS - 10mm | C18: IACS Member | F18: 10 | H18: =D18*E18*F18*7.85 | I18: =IF(E18<0.6,1.2,1.05) | J18: =H18*I18*G18 | K18: 36000 | L18: =J18*K18
A19: 12 | B19: Plate IACS - 12mm | C19: IACS Member | F19: 12 | H19: =D19*E19*F19*7.85 | I19: =IF(E19<0.6,1.2,1.05) | J19: =H19*I19*G19 | K19: 36000 | L19: =J19*K19

Sheet 💲 MASTER HARGA
A1: 💲 MASTER HARGA SATUAN - DATABASE TARIF GALANGAN
A2: 📋 Database harga satuan untuk generate quotation otomatis. Update harga di kolom KUNING.
A4: I. PELAYANAN UMUM
A5: Kode | B5: Item Pekerjaan | C5: Satuan | D5: Harga Satuan (Rp) | E5: Kategori Biaya | F5: Keterangan | G5: Last Update
A6: I.a | B6: Docking-Undocking | C6: Ls | D6: 18750000 | E6: Service | F6: Tarif tetap | G6: 2025-04
A7: I.b | B7: Asistensi Tali Temali Dari Darat dan Persiapan Ganjal | C7: Ls | D7: 4400000 | E7: Service | F7: Tarif tetap | G7: 2025-04
A8: I.c | B8: Asistensi Dengan Mooring Boat | C8: Ls | D8: 6100000 | E8: Service | F8: Tarif tetap | G8: 2025-04
A9: I.d | B9: Sewa Dok Selama Perbaikan | C9: Hari | D9: 1650000 | E9: Service | F9: Per hari | G9: 2025-04
A10: I.e | B10: Sewa Tempat Sandar (after repair) | C10: Hari | D10: 400000 | E10: Service | F10: Per hari | G10: 2025-04
A11: I.f | B11: Penyambungan Listrik Darat Ke Kapal | C11: Ls | D11: 950000 | E11: Service | F11: Tarif tetap | G11: 2025-04
A12: I.g | B12: Suplai Listrik 3A 380V selama ditas dock dan sandar | C12: Hari | D12: 650000 | E12: Service | F12: Per hari | G12: 2025-04
A13: I.h | B13: Disediakan Fasilitas MCK untuk ABK | C13: Ls | D13: 1650000 | E13: Service | F13: Tarif tetap | G13: 2025-04
A14: I.i | B14: Disediakan Tempat Penampungan Sampah | C14: Ls | D14: 1650000 | E14: Service | F14: Tarif tetap | G14: 2025-04
A15: I.j | B15: Disediakan Tempat Penyimpanan Material Untuk Kapal | C15: Ls | D15: 2200000 | E15: Service | F15: Tarif tetap | G15: 2025-04
A16: I.k | B16: Penggunaan Alat Angkat (< 1.5 Ton) | C16: Ls | D16: 10000000 | E16: Service | F16: Tarif tetap | G16: 2025-04
A17: I.l | B17: Suplai Air Tawar | C17: Ton | D17: 90000 | E17: Service | F17: Per ton | G17: 2025-04
A18: I.m | B18: Disediakan Tempat Penampungan Limbah B3 ≤ 2 Ton | C18: Ton | D18: 7150000 | E18: Service | F18: Include bea treatment | G18: 2025-04
A20: II. PERAWATAN LAMBUNG (Blasting & Painting)
A21: Kode | B21: Item Pekerjaan | C21: Satuan | D21: Harga Satuan (Rp) | E21: Kategori Biaya | F21: Keterangan | G21: Last Update
A22: II.a | B22: Sekrap Bagian Bawah Air | C22: m2 | D22: 8000 | E22: Service | F22: Manual scraping | G22: 2025-04
A23: II.b | B23: Sandblasting Bottom Sampai Waterline (S.A 2.0) | C23: m2 | D23: 80000 | E23: Service | F23: SA 2.0 full blast. Sweep Spot: Rp 70,000/m² | G23: 2025-04
A24: II.c | B24: Sandblasting Top Side (S.A 2.0) | C24: m2 | D24: 80000 | E24: Service | F24: SA 2.0 full blast. Sweep Spot: Rp 70,000/m² | G24: 2025-04
A25: II.d | B25: Sandblasting Bulwark Luar (S.A 2.0) | C25: m2 | D25: 80000 | E25: Service | F25: SA 2.0 full blast. Sweep Spot: Rp 70,000/m² | G25: 2025-04
A26: II.e | B26: Sandblasting Main Deck Sweep Blast | C26: m2 | D26: 500 | E26: Service | F26: Sweep blast | G26: 2025-04
A27: II.f | B27: Cuci Air Tawar | C27: m2 | D27: 7500 | E27: Service | F27: Fresh water wash | G27: 2025-04
A28: II.g | B28: Pengecatan Bottom sampai waterline (1x Primer, 1x Sealer, 1x AF) | C28: m2 | D28: 24000 | E28: Service | F28: 2 coat system | G28: 2025-04
A29: II.h | B29: Pengecatan Top Side (1x Primer dan 1x Top Coat) | C29: m2 | D29: 16000 | E29: Service | F29: 2 coat system | G29: 2025-04
A30: II.i | B30: Pengecatan Bulwark Luar (1x Primer dan 1x Top Coat) | C30: m2 | D30: 16000 | E30: Service | F30: 2 coat system | G30: 2025-04
A31: II.j | B31: Pengecatan Main Deck (1x Primer dan 1x Top Coat) | C31: m2 | D31: 16000 | E31: Service | F31: 2 coat system | G31: 2025-04
A32: II.k | B32: Pengecatan Draft Mark, Nama Kapal | C32: Ls | D32: 1350000 | E32: Service | F32: Tarif tetap | G32: 2025-04
A33: II.l | B33: Pemasangan Zinc Anode | C33: pcs | D33: 150000 | E33: Material | F33: Per piece | G33: 2025-04
A35: III. SEACHEST & VALVE
A36: Kode | B36: Item Pekerjaan | C36: Satuan | D36: Harga Satuan (Rp) | E36: Kategori Biaya | F36: Keterangan | G36: Last Update
A37: III.a | B37: Buka dan Tutup Kembali Saringan Luar dan Pembersihan Kotak Seachest | C37: bh | D37: 1900000 | E37: Service | F37: Per unit | G37: 2025-04
A38: III.b | B38: Perawatan Saringan Air Dalam | C38: bh | D38: 1450000 | E38: Service | F38: Per unit | G38: 2025-04
A39: III.c | B39: Perawatan Seachest Valve 6" | C39: bh | D39: 1900000 | E39: Service | F39: Per unit | G39: 2025-04
A41: IV. SISTEM PENGGERAK KAPAL
A42: Kode | B42: Item Pekerjaan | C42: Satuan | D42: Harga Satuan (Rp) | E42: Kategori Biaya | F42: Keterangan | G42: Last Update
A43: IV.a | B43: Pengukuran Clearance Shaft | C43: Titik | D43: 650000 | E43: Service | F43: Per titik | G43: 2025-04
A44: IV.b | B44: Buka dan pasang kembali penahan rymers packing | C44: bh | D44: 1000000 | E44: Service | F44: Per unit | G44: 2025-04
...

Sheet 📄 QUOTATION
A1: 📄 QUOTATION GENERATOR - PENAWARAN OTOMATIS
A2: 📋 Quotation otomatis dari Calculator. Volume & Harga terhubung ke sheet lain. Copy ke template MKT-FM-002.
A4: PROJECT INFORMATION
A5: No Quotation: | D5: Nama Kapal: | E5: ='📝 INPUT DATA'!C6
A6: Revision: | B6: 00 | D6: Panjang: | E6: ='📝 INPUT DATA'!C8
A7: Client: | D7: Lebar: | E7: ='📝 INPUT DATA'!C9
A8: Contact: | D8: Sarat: | E8: ='📝 INPUT DATA'!C10
A10: DAFTAR ITEM PEKERJAAN
A11: No | B11: Poke | C11: Item Pekerjaan | D11: Volume | E11: Satuan | F11: Harga Satuan | G11: Service | H11: Material | I11: Catatan
A12: I | C12: PELAYANAN UMUM
B13: a | C13: Docking-Undocking | D13: 1 | E13: Ls | F13: =VLOOKUP("I.a",'💲 MASTER HARGA'!A:D,4,FALSE) | G13: =IFERROR(D13*F13,0)
B14: b | C14: Asistensi Tali Temali Dari Darat dan Persiapan Ganjal | D14: 1 | E14: Ls | F14: =VLOOKUP("I.b",'💲 MASTER HARGA'!A:D,4,FALSE) | G14: =IFERROR(D14*F14,0)
B15: c | C15: Asistensi Dengan Mooring Boat | D15: 1 | E15: Ls | F15: =VLOOKUP("I.c",'💲 MASTER HARGA'!A:D,4,FALSE) | G15: =IFERROR(D15*F15,0)
B16: d | C16: Sewa Dok Selama Perbaikan | D16: 30 | E16: Hari | F16: =VLOOKUP("I.d",'💲 MASTER HARGA'!A:D,4,FALSE) | G16: =IFERROR(D16*F16,0)
B17: e | C17: Sewa Tempat Sandar (after repair) | D17: 3 | E17: Hari | F17: =VLOOKUP("I.e",'💲 MASTER HARGA'!A:D,4,FALSE) | G17: =IFERROR(D17*F17,0)
B18: f | C18: Penyambungan Listrik Darat Ke Kapal | D18: 1 | E18: Ls | F18: =VLOOKUP("I.f",'💲 MASTER HARGA'!A:D,4,FALSE) | G18: =IFERROR(D18*F18,0)
B19: g | C19: Suplai Listrik 3A 380V selama ditas dock dan sandar | D19: 33 | E19: Hari | F19: =VLOOKUP("I.g",'💲 MASTER HARGA'!A:D,4,FALSE) | G19: =IFERROR(D19*F19,0)
B20: h | C20: Disediakan Fasilitas MCK untuk ABK | D20: 1 | E20: Ls | F20: =VLOOKUP("I.h",'💲 MASTER HARGA'!A:D,4,FALSE) | G20: =IFERROR(D20*F20,0)
B21: i | C21: Disediakan Tempat Penampungan Sampah | D21: 1 | E21: Ls | F21: =VLOOKUP("I.i",'💲 MASTER HARGA'!A:D,4,FALSE) | G21: =IFERROR(D21*F21,0)
B22: j | C22: Disediakan Tempat Penyimpanan Material Untuk Kapal | D22: 1 | E22: Ls | F22: =VLOOKUP("I.j",'💲 MASTER HARGA'!A:D,4,FALSE) | G22: =IFERROR(D22*F22,0)
B23: k | C23: Penggunaan Alat Angkat (< 1.5 Ton) | D23: 1 | E23: Ls | F23: =VLOOKUP("I.k",'💲 MASTER HARGA'!A:D,4,FALSE) | G23: =IFERROR(D23*F23,0)
B24: l | C24: Suplai Air Tawar | D24: 20 | E24: Ton | F24: =VLOOKUP("I.l",'💲 MASTER HARGA'!A:D,4,FALSE) | G24: =IFERROR(D24*F24,0)
B25: m | C25: Disediakan Tempat Penampungan Limbah B3 ≤ 2 Ton | D25: 3 | E25: Ton | F25: =VLOOKUP("I.m",'💲 MASTER HARGA'!A:D,4,FALSE) | G25: =IFERROR(D25*F25,0)
A26: II | C26: PERAWATAN LAMBUNG (Material Suplai Owner)
B27: a | C27: Sekrap Bagian Bawah Air | D27: ='🎨 DETAIL B&P'!I16 | E27: m2 | F27: =VLOOKUP("II.a",'💲 MASTER HARGA'!A:D,4,FALSE) | G27: =IFERROR(D27*F27,0)
B28: b | C28: Sandblasting Bottom Sampai Waterline (S.A 2.0) | D28: ='🎨 DETAIL B&P'!I16 | E28: m2 | F28: =VLOOKUP("II.b",'💲 MASTER HARGA'!A:D,4,FALSE) | G28: =IFERROR(D28*F28,0)
B29: c | C29: Sandblasting Top Side (S.A 2.0) | D29: ='🎨 DETAIL B&P'!I21 | E29: m2 | F29: =VLOOKUP("II.c",'💲 MASTER HARGA'!A:D,4,FALSE) | G29: =IFERROR(D29*F29,0)
B30: d | C30: Sandblasting Bulwark Luar (S.A 2.0) | D30: ='🎨 DETAIL B&P'!I25 | E30: m2 | F30: =VLOOKUP("II.d",'💲 MASTER HARGA'!A:D,4,FALSE) | G30: =IFERROR(D30*F30,0)
B31: e | C31: Sandblasting Main Deck Sweep Blast | D31: ='🎨 DETAIL B&P'!I29 | E31: m2 | F31: =VLOOKUP("II.e",'💲 MASTER HARGA'!A:D,4,FALSE) | G31: =IFERROR(D31*F31,0)
B32: f | C32: Cuci Air Tawar | D32: ='🎨 DETAIL B&P'!I16 | E32: m2 | F32: =VLOOKUP("II.f",'💲 MASTER HARGA'!A:D,4,FALSE) | G32: =IFERROR(D32*F32,0)
B33: g | C33: Pengecatan Bottom sampai waterline (1x Primer, 1x Sealer, 1x AF) | D33: ='🎨 DETAIL B&P'!I16 | E33: m2 | F33: =VLOOKUP("II.g",'💲 MASTER HARGA'!A:D,4,FALSE) | G33: =IFERROR(D33*F33,0)
B34: h | C34: Pengecatan Top Side (1x Primer dan 1x Top Coat) | D34: ='🎨 DETAIL B&P'!I21 | E34: m2 | F34: =VLOOKUP("II.h",'💲 MASTER HARGA'!A:D,4,FALSE) | G34: =IFERROR(D34*F34,0)
B35: i | C35: Pengecatan Bulwark Luar (1x Primer dan 1x Top Coat) | D35: ='🎨 DETAIL B&P'!I25 | E35: m2 | F35: =VLOOKUP("II.i",'💲 MASTER HARGA'!A:D,4,FALSE) | G35: =IFERROR(D35*F35,0)
B36: j | C36: Pengecatan Main Deck (1x Primer dan 1x Top Coat) | D36: ='🎨 DETAIL B&P'!I29 | E36: m2 | F36: =VLOOKUP("II.j",'💲 MASTER HARGA'!A:D,4,FALSE) | G36: =IFERROR(D36*F36,0)
B37: k | C37: Pengecatan Draft Mark, Nama Kapal | D37: 1 | E37: Ls | F37: =VLOOKUP("II.k",'💲 MASTER HARGA'!A:D,4,FALSE) | G37: =IFERROR(D37*F37,0)
B38: l | C38: Pemasangan Zinc Anode | D38: 29 | E38: pcs | F38: =VLOOKUP("II.l",'💲 MASTER HARGA'!A:D,4,FALSE) | H38: =IFERROR(D38*F38,0)
A41: Total | G41: =SUM(G12:G39) | H41: =SUM(H12:H39)
A42: GRAND TOTAL | G42: =G41+H41

Sheet 📊 ANALYTICS
A1: 📊 ANALYTICS DASHBOARD - RINGKASAN TERINTEGRASI
A2: 📋 Ringkasan otomatis dari semua calculator. Dual View: PPIC (Teknis) & Marketing (Komersial)
A4: A. DATA KAPAL
A5: Jenis Kapal: | B5: ='📝 INPUT DATA'!C7 | C5: Kondisi: | D5: ='📝 INPUT DATA'!C13
A6: Panjang: | B6: ='📝 INPUT DATA'!C8 | C6: m
A7: Lebar: | B7: ='📝 INPUT DATA'!C9 | C7: m
A8: Depth: | B8: ='📝 INPUT DATA'!C10 | C8: m
A9: Sarat (auto): | B9: ='📝 INPUT DATA'!C11 | C9: m
A10: Block Coef: | B10: ='📝 INPUT DATA'!C19 | C10: -
A11: Faktor WSA: | B11: ='📝 INPUT DATA'!C20 | C11: -
A12: Faktor Kondisi: | B12: ='📝 INPUT DATA'!C24 | C12: x
A15: B. PPIC VIEW (Teknis)
A16: No | B16: Kategori | C16: Hasil | D16: Satuan | E16: Man-Hour | F16: Man-Day | G16: Source
A17: 1 | B17: Total Luasan B&P | C17: ='🎨 DETAIL B&P'!I41 | D17: m² | E17: ='🎨 DETAIL B&P'!B47 | F17: ='🎨 DETAIL B&P'!B48 | G17: Detail B&P
A18: 2 | B18: Total MH Piping | C18: ='🔧 DETAIL PIPING'!H19 | D18: MH | E18: ='🔧 DETAIL PIPING'!H19 | F18: ='🔧 DETAIL PIPING'!H21 | G18: Detail Piping
A19: 3 | B19: Total Berat Replating | C19: ='⚙️ DETAIL REPLATING'!J6 | D19: kg | E19: =IFERROR(C19/40,0) | F19: =IFERROR(E19/8,0) | G19: Detail Replating
A21: GRAND TOTAL MAN-DAY | E21: =SUM(E17:E19) | F21: =SUM(F17:F19) | G21: MD
A24: C. MARKETING VIEW (Komersial)
A25: No | B25: Item Biaya | C25: Qty | D25: Satuan | E25: Harga Satuan | F25: Total (Rp) | G25: Keterangan
A26: 1 | B26: Biaya Man-Hour | C26: =E21 | D26: MH | E26: 50000 | F26: =IFERROR(C26*E26,0) | G26: Total MH × Rate
A27: 2 | B27: Biaya Material Baja | C27: =C19 | D27: kg | E27: 32000 | F27: =IFERROR(C27*E27,0) | G27: Berat × Harga/kg
A28: 3 | B28: Biaya Coating B&P | C28: =C17 | D28: m² | E28: 120000 | F28: =IFERROR(C28*E28,0) | G28: Luasan × Harga komposit/m²
A29: 4 | B29: Biaya Disposal Limbah | C29: 5 | D29: m³ | E29: 500000 | F29: =IFERROR(C29*E29,0) | G29: Estimasi disposal
B31: SUBTOTAL BIAYA PRODUKSI | F31: =SUM(F26:F29)
B32: Overhead (15%) | F32: =F31*0.15
B33: Margin (25%) | F33: =F31*0.25
A35: 🎯 GRAND TOTAL HARGA PENAWARAN | F35: =F31+F32+F33 | G35: Rp
